Workbook

Sheet Summary
A1: Pakistan COVID-19 — Data Analysis Report
A2: ="Data period: "&TEXT(Daily!A5,"d mmm yyyy")&" – "&TEXT(Daily!A103,"d mmm yyyy")&" · "&COUNT(Daily!A5:A103)&" calendar days · "&TEXT(COUNTA(Data!$A$2:$A$2797),"#,##0")&" case records · source: PK_COVID_Dashboard.xlsx (Clean sheet)" -> Data period: 26 Feb 2020 – 3 Jun 2020 · 99 calendar days · 2,796 case records · source: PK_COVID_Dashboard.xlsx (Clean sheet)
A4: TOTAL CASES | C4: TOTAL DEATHS | E4: RECOVERED | G4: ACTIVE CASES
A5: =SUM(Data!$B$2:$B$2797) -> 83985 | C5: =SUM(Data!$C$2:$C$2797) -> 1728 | E5: =SUM(Data!$D$2:$D$2797) -> 24753 | G5: =A5-C5-E5 -> 57504
A6: confirmed | C6: reported | E6: reported (under-counted) | G6: derived: cases − deaths − recovered
A8: CASE FATALITY RATE | C8: REPORTED RECOVERY RATE | E8: PEAK SINGLE DAY | G8: LATEST 7-DAY AVERAGE
A9: =C5/A5 -> 0.020575103 | C9: =E5/A5 -> 0.2947312 | E9: =MAX(Daily!$C$5:$C$103) -> 4677 | G9: =Daily!J103 -> 3374
A10: deaths ÷ cases (crude) | C10: recovered ÷ cases | E10: =TEXT(INDEX(Daily!$A$5:$A$103,MATCH(E9,Daily!$C$5:$C$103,0)),"d mmm yyyy") -> 3 Jun 2020 | G10: =TEXT(Daily!A103,"d mmm yyyy")&" · cases per day" -> 3 Jun 2020 · cases per day
A12: Key findings
A13: ="1. Scale — "&TEXT(A5,"#,##0")&" confirmed cases and "&TEXT(C5,"#,##0")&" deaths in "&COUNT(Daily!A5:A103)&" days: a crude fatality rate of "&TEXT(A9,"0.00%")&", averaging "&TEXT(A5/COUNT(Daily!A5:A103),"#,##0")&" new cases a day." -> 1. Scale — 83,985 confirmed cases and 1,728 deaths in 99 days: a crude fatality rate of 2.06%, averaging 848 new cases a day.
A14: ="2. Momentum — the 7-day average reached "&TEXT(G9,"#,##0")&" cases a day on "&TEXT(Daily!A103,"d mmm")&", "&TEXT(Daily!M103,"+0%;-0%")&" on a week earlier. "&IF(INDEX(Daily!$A$5:$A$103,MATCH(E9,Daily!$C$5:$C$103,0))=Daily!A103,"The highest single day ("&TEXT(E9,"#,##0")&") is the last day in the data, so the outbreak had not peaked.","The highest single day was "&TEXT(E9,"#,##0")&".") -> 2. Momentum — the 7-day average reached 3,374 cases a day on 3 Jun, +81% on a week earlier. The highest single day (4,677) is the last day in the data, so the outbreak had not peaked.
A15: ="3. Timing — May alone produced "&TEXT(Monthly!I8,"0%")&" of all cases ("&TEXT(Monthly!F8,"#,##0")&" a day vs "&TEXT(Monthly!F7,"#,##0")&" in April). Early-surge cases doubled roughly every "&TEXT(Statistics!G52,"0.0")&" days ("&TEXT(Statistics!B52,"d mmm")&" – "&TEXT(Statistics!C52,"d mmm")&"); the daily growth rate then slowed to "&TEXT(Statistics!F53,"0.0%")&" in the peak phase." -> 3. Timing — May alone produced 65% of all cases (1,769 a day vs 480 in April). Early-surge cases doubled roughly every 10.1 days (15 Mar – 30 Apr); the daily growth rate then slowed to 3.1% in the peak phase.
A16: ="4. Geography — "&Province!A5&" and "&Province!A6&" together account for "&TEXT(Province!F5+Province!F6,"0%")&" of cases; "&City!B5&" and "&City!B6&" alone make up "&TEXT(City!H6,"0%")&", and the top five cities "&TEXT(City!H9,"0%")&"." -> 4. Geography — Sindh and Punjab together account for 76% of cases; Karachi and Lahore alone make up 68%, and the top five cities 84%.
A17: ="5. Mortality — "&Province!B15&" has the highest CFR among provinces with "&TEXT(Province!B14,"#,##0")&"+ cases ("&TEXT(Province!C15,"0.0%")&", "&TEXT(Province!C15/Province!H13,"0.0")&"× the national rate): "&TEXT(INDEX(Province!G5:G12,MATCH(Province!B15,Province!A5:A12,0)),"0%")&" of deaths from "&TEXT(INDEX(Province!F5:F12,MATCH(Province!B15,Province!A5:A12,0)),"0%")&" of cases." -> 5. Mortality — Khyber Pakhtunkhwa has the highest CFR among provinces with 1,000+ cases (4.6%, 2.2× the national rate): 27% of deaths from 12% of cases.
A18: ="6. Source of infection — "&TEXT(Travel!D24,"0.0%")&" of cases are recorded as local transmission, "&TEXT(Travel!D27,"0.0%")&" have no known source, "&TEXT(Travel!D25,"0.0%")&" are tied to clusters (Tableeghi Jamaat, jail) and only "&TEXT(Travel!D26,"0.0%")&" to travel." -> 6. Source of infection — 93.0% of cases are recorded as local transmission, 4.1% have no known source, 1.5% are tied to clusters (Tableeghi Jamaat, jail) and only 1.4% to travel.
A19: ="7. Cases and deaths move together — daily deaths correlate with daily cases at r = "&TEXT(Statistics!B39,"0.00")&" on the same day and "&TEXT(Statistics!B46,"0.00")&" at a "&Statistics!A46&"-day lag. Both series rise together, so the data cannot isolate the reporting delay; treat as indicative only." -> 7. Cases and deaths move together — daily deaths correlate with daily cases at r = 0.93 on the same day and 0.81 at a 14-day lag. Both series rise together, so the data cannot isolate the reporting delay; treat as indicative only.
A20: ="8. Data caveat — among provinces with "&TEXT(Province!B14,"#,##0")&"+ cases, reported recovery rates range from "&TEXT(Province!B16,"0%")&" to "&TEXT(Province!C16,"0%")&". That spread reflects uneven reporting, so recoveries and Active Cases ("&TEXT(G5,"#,##0")&") are unreliable; cases and deaths are the dependable measures." -> 8. Data caveat — among provinces with 1,000+ cases, reported recovery rates range from 13% to 48%. That spread reflects uneven reporting, so recoveries and Active Cases (57,504) are unreliable; cases and deaths are the dependable measures.
A22: Implications
A23: • Monitor the 7-day average, not single days: daily counts swing widely and the series was still climbing at the end of the data.
A24: • Concentrate response capacity on the two big-city clusters (Karachi, Lahore) — together they hold well over half of all cases.
A25: • Review clinical capacity and case management in the province with the highest fatality rate; its deaths are out of proportion to its case count.
A26: • Standardise recovery reporting across provinces before using Active Cases or recovery rates for planning.
A27: • Treat the recorded source-of-infection field with caution: most cases default to "local", so it says little about how outbreaks start.

Sheet Daily
A1: Daily trend
A2: One row per calendar day (days with no reported records are shown as zero). All values are formulas on the Data sheet.
A4: Date | B4: Day | C4: Daily cases | D4: Daily deaths | E4: Daily recovered | F4: Cumulative cases | G4: Cumulative deaths | H4: Cumulative recovered | I4: Active cases | J4: 7-day avg cases | K4: 7-day avg deaths | L4: Cumulative CFR | M4: Week-on-week change (7-day avg) | N4: Day index | O4: Ln(7-day avg cases) | P4: Records
A5: =MIN(Data!$A$2:$A$2797) -> 43887 | B5: =CHOOSE(WEEKDAY(A5,2),"Mon","Tue","Wed","Thu","Fri","Sat","Sun") -> Wed | C5: =SUMIFS(Data!$B$2:$B$2797,Data!$A$2:$A$2797,A5) -> 3 | D5: =SUMIFS(Data!$C$2:$C$2797,Data!$A$2:$A$2797,A5) -> 0 | E5: =SUMIFS(Data!$D$2:$D$2797,Data!$A$2:$A$2797,A5) -> 0 | F5: =SUM($C$5:C5) -> 3 | G5: =SUM($D$5:D5) -> 0 | H5: =SUM($E$5:E5) -> 0 | I5: =F5-G5-H5 -> 3 | L5: =IF(F5>0,G5/F5,0) -> 0 | N5: =A5-$A$5 -> 0 | P5: =COUNTIF(Data!$A$2:$A$2797,A5) -> 2
A6: =A5+1 -> 43888 | B6: =CHOOSE(WEEKDAY(A6,2),"Mon","Tue","Wed","Thu","Fri","Sat","Sun") -> Thu | C6: =SUMIFS(Data!$B$2:$B$2797,Data!$A$2:$A$2797,A6) -> 0 | D6: =SUMIFS(Data!$C$2:$C$2797,Data!$A$2:$A$2797,A6) -> 0 | E6: =SUMIFS(Data!$D$2:$D$2797,Data!$A$2:$A$2797,A6) -> 0 | F6: =SUM($C$5:C6) -> 3 | G6: =SUM($D$5:D6) -> 0 | H6: =SUM($E$5:E6) -> 0 | I6: =F6-G6-H6 -> 3 | L6: =IF(F6>0,G6/F6,0) -> 0 | N6: =A6-$A$5 -> 1 | P6: =COUNTIF(Data!$A$2:$A$2797,A6) -> 0
A7: =A6+1 -> 43889 | B7: =CHOOSE(WEEKDAY(A7,2),"Mon","Tue","Wed","Thu","Fri","Sat","Sun") -> Fri | C7: =SUMIFS(Data!$B$2:$B$2797,Data!$A$2:$A$2797,A7) -> 0 | D7: =SUMIFS(Data!$C$2:$C$2797,Data!$A$2:$A$2797,A7) -> 0 | E7: =SUMIFS(Data!$D$2:$D$2797,Data!$A$2:$A$2797,A7) -> 0 | F7: =SUM($C$5:C7) -> 3 | G7: =SUM($D$5:D7) -> 0 | H7: =SUM($E$5:E7) -> 0 | I7: =F7-G7-H7 -> 3 | L7: =IF(F7>0,G7/F7,0) -> 0 | N7: =A7-$A$5 -> 2 | P7: =COUNTIF(Data!$A$2:$A$2797,A7) -> 0
A8: =A7+1 -> 43890 | B8: =CHOOSE(WEEKDAY(A8,2),"Mon","Tue","Wed","Thu","Fri","Sat","Sun") -> Sat | C8: =SUMIFS(Data!$B$2:$B$2797,Data!$A$2:$A$2797,A8) -> 2 | D8: =SUMIFS(Data!$C$2:$C$2797,Data!$A$2:$A$2797,A8) -> 0 | E8: =SUMIFS(Data!$D$2:$D$2797,Data!$A$2:$A$2797,A8) -> 0 | F8: =SUM($C$5:C8) -> 5 | G8: =SUM($D$5:D8) -> 0 | H8: =SUM($E$5:E8) -> 0 | I8: =F8-G8-H8 -> 5 | L8: =IF(F8>0,G8/F8,0) -> 0 | N8: =A8-$A$5 -> 3 | P8: =COUNTIF(Data!$A$2:$A$2797,A8) -> 2
A9: =A8+1 -> 43891 | B9: =CHOOSE(WEEKDAY(A9,2),"Mon","Tue","Wed","Thu","Fri","Sat","Sun") -> Sun | C9: =SUMIFS(Data!$B$2:$B$2797,Data!$A$2:$A$2797,A9) -> 0 | D9: =SUMIFS(Data!$C$2:$C$2797,Data!$A$2:$A$2797,A9) -> 0 | E9: =SUMIFS(Data!$D$2:$D$2797,Data!$A$2:$A$2797,A9) -> 0 | F9: =SUM($C$5:C9) -> 5 | G9: =SUM($D$5:D9) -> 0 | H9: =SUM($E$5:E9) -> 0 | I9: =F9-G9-H9 -> 5 | L9: =IF(F9>0,G9/F9,0) -> 0 | N9: =A9-$A$5 -> 4 | P9: =COUNTIF(Data!$A$2:$A$2797,A9) -> 0
A10: =A9+1 -> 43892 | B10: =CHOOSE(WEEKDAY(A10,2),"Mon","Tue","Wed","Thu","Fri","Sat","Sun") -> Mon | C10: =SUMIFS(Data!$B$2:$B$2797,Data!$A$2:$A$2797,A10) -> 1 | D10: =SUMIFS(Data!$C$2:$C$2797,Data!$A$2:$A$2797,A10) -> 0 | E10: =SUMIFS(Data!$D$2:$D$2797,Data!$A$2:$A$2797,A10) -> 0 | F10: =SUM($C$5:C10) -> 6 | G10: =SUM($D$5:D10) -> 0 | H10: =SUM($E$5:E10) -> 0 | I10: =F10-G10-H10 -> 6 | L10: =IF(F10>0,G10/F10,0) -> 0 | N10: =A10-$A$5 -> 5 | P10: =COUNTIF(Data!$A$2:$A$2797,A10) -> 1
A11: =A10+1 -> 43893 | B11: =CHOOSE(WEEKDAY(A11,2),"Mon","Tue","Wed","Thu","Fri","Sat","Sun") -> Tue | C11: =SUMIFS(Data!$B$2:$B$2797,Data!$A$2:$A$2797,A11) -> 0 | D11: =SUMIFS(Data!$C$2:$C$2797,Data!$A$2:$A$2797,A11) -> 0 | E11: =SUMIFS(Data!$D$2:$D$2797,Data!$A$2:$A$2797,A11) -> 0 | F11: =SUM($C$5:C11) -> 6 | G11: =SUM($D$5:D11) -> 0 | H11: =SUM($E$5:E11) -> 0 | I11: =F11-G11-H11 -> 6 | J11: =AVERAGE(C5:C11) -> 0.85714286 | K11: =AVERAGE(D5:D11) -> 0 | L11: =IF(F11>0,G11/F11,0) -> 0 | N11: =A11-$A$5 -> 6 | O11: =IF(J11>0,LN(J11),"") -> -0.15415068 | P11: =COUNTIF(Data!$A$2:$A$2797,A11) -> 0
A12: =A11+1 -> 43894 | B12: =CHOOSE(WEEKDAY(A12,2),"Mon","Tue","Wed","Thu","Fri","Sat","Sun") -> Wed | C12: =SUMIFS(Data!$B$2:$B$2797,Data!$A$2:$A$2797,A12) -> 0 | D12: =SUMIFS(Data!$C$2:$C$2797,Data!$A$2:$A$2797,A12) -> 0 | E12: =SUMIFS(Data!$D$2:$D$2797,Data!$A$2:$A$2797,A12) -> 0 | F12: =SUM($C$5:C12) -> 6 | G12: =SUM($D$5:D12) -> 0 | H12: =SUM($E$5:E12) -> 0 | I12: =F12-G12-H12 -> 6 | J12: =AVERAGE(C6:C12) -> 0.42857143 | K12: =AVERAGE(D6:D12) -> 0 | L12: =IF(F12>0,G12/F12,0) -> 0 | N12: =A12-$A$5 -> 7 | O12: =IF(J12>0,LN(J12),"") -> -0.84729786 | P12: =COUNTIF(Data!$A$2:$A$2797,A12) -> 0
A13: =A12+1 -> 43895 | B13: =CHOOSE(WEEKDAY(A13,2),"Mon","Tue","Wed","Thu","Fri","Sat","Sun") -> Thu | C13: =SUMIFS(Data!$B$2:$B$2797,Data!$A$2:$A$2797,A13) -> 0 | D13: =SUMIFS(Data!$C$2:$C$2797,Data!$A$2:$A$2797,A13) -> 0 | E13: =SUMIFS(Data!$D$2:$D$2797,Data!$A$2:$A$2797,A13) -> 0 | F13: =SUM($C$5:C13) -> 6 | G13: =SUM($D$5:D13) -> 0 | H13: =SUM($E$5:E13) -> 0 | I13: =F13-G13-H13 -> 6 | J13: =AVERAGE(C7:C13) -> 0.42857143 | K13: =AVERAGE(D7:D13) -> 0 | L13: =IF(F13>0,G13/F13,0) -> 0 | N13: =A13-$A$5 -> 8 | O13: =IF(J13>0,LN(J13),"") -> -0.84729786 | P13: =COUNTIF(Data!$A$2:$A$2797,A13) -> 0
A14: =A13+1 -> 43896 | B14: =CHOOSE(WEEKDAY(A14,2),"Mon","Tue","Wed","Thu","Fri","Sat","Sun") -> Fri | C14: =SUMIFS(Data!$B$2:$B$2797,Data!$A$2:$A$2797,A14) -> 0 | D14: =SUMIFS(Data!$C$2:$C$2797,Data!$A$2:$A$2797,A14) -> 0 | E14: =SUMIFS(Data!$D$2:$D$2797,Data!$A$2:$A$2797,A14) -> 1 | F14: =SUM($C$5:C14) -> 6 | G14: =SUM($D$5:D14) -> 0 | H14: =SUM($E$5:E14) -> 1 | I14: =F14-G14-H14 -> 5 | J14: =AVERAGE(C8:C14) -> 0.42857143 | K14: =AVERAGE(D8:D14) -> 0 | L14: =IF(F14>0,G14/F14,0) -> 0 | N14: =A14-$A$5 -> 9 | O14: =IF(J14>0,LN(J14),"") -> -0.84729786 | P14: =COUNTIF(Data!$A$2:$A$2797,A14) -> 1
A15: =A14+1 -> 43897 | B15: =CHOOSE(WEEKDAY(A15,2),"Mon","Tue","Wed","Thu","Fri","Sat","Sun") -> Sat | C15: =SUMIFS(Data!$B$2:$B$2797,Data!$A$2:$A$2797,A15) -> 1 | D15: =SUMIFS(Data!$C$2:$C$2797,Data!$A$2:$A$2797,A15) -> 0 | E15: =SUMIFS(Data!$D$2:$D$2797,Data!$A$2:$A$2797,A15) -> 0 | F15: =SUM($C$5:C15) -> 7 | G15: =SUM($D$5:D15) -> 0 | H15: =SUM($E$5:E15) -> 1 | I15: =F15-G15-H15 -> 6 | J15: =AVERAGE(C9:C15) -> 0.28571429 | K15: =AVERAGE(D9:D15) -> 0 | L15: =IF(F15>0,G15/F15,0) -> 0 | N15: =A15-$A$5 -> 10 | O15: =IF(J15>0,LN(J15),"") -> -1.252763 | P15: =COUNTIF(Data!$A$2:$A$2797,A15) -> 1
A16: =A15+1 -> 43898 | B16: =CHOOSE(WEEKDAY(A16,2),"Mon","Tue","Wed","Thu","Fri","Sat","Sun") -> Sun | C16: =SUMIFS(Data!$B$2:$B$2797,Data!$A$2:$A$2797,A16) -> 0 | D16: =SUMIFS(Data!$C$2:$C$2797,Data!$A$2:$A$2797,A16) -> 0 | E16: =SUMIFS(Data!$D$2:$D$2797,Data!$A$2:$A$2797,A16) -> 0 | F16: =SUM($C$5:C16) -> 7 | G16: =SUM($D$5:D16) -> 0 | H16: =SUM($E$5:E16) -> 1 | I16: =F16-G16-H16 -> 6 | J16: =AVERAGE(C10:C16) -> 0.28571429 | K16: =AVERAGE(D10:D16) -> 0 | L16: =IF(F16>0,G16/F16,0) -> 0 | N16: =A16-$A$5 -> 11 | O16: =IF(J16>0,LN(J16),"") -> -1.252763 | P16: =COUNTIF(Data!$A$2:$A$2797,A16) -> 0
A17: =A16+1 -> 43899 | B17: =CHOOSE(WEEKDAY(A17,2),"Mon","Tue","Wed","Thu","Fri","Sat","Sun") -> Mon | C17: =SUMIFS(Data!$B$2:$B$2797,Data!$A$2:$A$2797,A17) -> 9 | D17: =SUMIFS(Data!$C$2:$C$2797,Data!$A$2:$A$2797,A17) -> 0 | E17: =SUMIFS(Data!$D$2:$D$2797,Data!$A$2:$A$2797,A17) -> 0 | F17: =SUM($C$5:C17) -> 16 | G17: =SUM($D$5:D17) -> 0 | H17: =SUM($E$5:E17) -> 1 | I17: =F17-G17-H17 -> 15 | J17: =AVERAGE(C11:C17) -> 1.4285714 | K17: =AVERAGE(D11:D17) -> 0 | L17: =IF(F17>0,G17/F17,0) -> 0 | N17: =A17-$A$5 -> 12 | O17: =IF(J17>0,LN(J17),"") -> 0.35667494 | P17: =COUNTIF(Data!$A$2:$A$2797,A17) -> 2
A18: =A17+1 -> 43900 | B18: =CHOOSE(WEEKDAY(A18,2),"Mon","Tue","Wed","Thu","Fri","Sat","Sun") -> Tue | C18: =SUMIFS(Data!$B$2:$B$2797,Data!$A$2:$A$2797,A18) -> 3 | D18: =SUMIFS(Data!$C$2:$C$2797,Data!$A$2:$A$2797,A18) -> 0 | E18: =SUMIFS(Data!$D$2:$D$2797,Data!$A$2:$A$2797,A18) -> 0 | F18: =SUM($C$5:C18) -> 19 | G18: =SUM($D$5:D18) -> 0 | H18: =SUM($E$5:E18) -> 1 | I18: =F18-G18-H18 -> 18 | J18: =AVERAGE(C12:C18) -> 1.8571429 | K18: =AVERAGE(D12:D18) -> 0 | L18: =IF(F18>0,G18/F18,0) -> 0 | M18: =IF(J11>0,J18/J11-1,"") -> 1.1666667 | N18: =A18-$A$5 -> 13 | O18: =IF(J18>0,LN(J18),"") -> 0.61903921 | P18: =COUNTIF(Data!$A$2:$A$2797,A18) -> 3
A19: =A18+1 -> 43901 | B19: =CHOOSE(WEEKDAY(A19,2),"Mon","Tue","Wed","Thu","Fri","Sat","Sun") -> Wed | C19: =SUMIFS(Data!$B$2:$B$2797,Data!$A$2:$A$2797,A19) -> 1 | D19: =SUMIFS(Data!$C$2:$C$2797,Data!$A$2:$A$2797,A19) -> 0 | E19: =SUMIFS(Data!$D$2:$D$2797,Data!$A$2:$A$2797,A19) -> 1 | F19: =SUM($C$5:C19) -> 20 | G19: =SUM($D$5:D19) -> 0 | H19: =SUM($E$5:E19) -> 2 | I19: =F19-G19-H19 -> 18 | J19: =AVERAGE(C13:C19) -> 2 | K19: =AVERAGE(D13:D19) -> 0 | L19: =IF(F19>0,G19/F19,0) -> 0 | M19: =IF(J12>0,J19/J12-1,"") -> 3.6666667 | N19: =A19-$A$5 -> 14 | O19: =IF(J19>0,LN(J19),"") -> 0.69314718 | P19: =COUNTIF(Data!$A$2:$A$2797,A19) -> 2
A20: =A19+1 -> 43902 | B20: =CHOOSE(WEEKDAY(A20,2),"Mon","Tue","Wed","Thu","Fri","Sat","Sun") -> Thu | C20: =SUMIFS(Data!$B$2:$B$2797,Data!$A$2:$A$2797,A20) -> 1 | D20: =SUMIFS(Data!$C$2:$C$2797,Data!$A$2:$A$2797,A20) -> 0 | E20: =SUMIFS(Data!$D$2:$D$2797,Data!$A$2:$A$2797,A20) -> 0 | F20: =SUM($C$5:C20) -> 21 | G20: =SUM($D$5:D20) -> 0 | H20: =SUM($E$5:E20) -> 2 | I20: =F20-G20-H20 -> 19 | J20: =AVERAGE(C14:C20) -> 2.1428571 | K20: =AVERAGE(D14:D20) -> 0 | L20: =IF(F20>0,G20/F20,0) -> 0 | M20: =IF(J13>0,J20/J13-1,"") -> 4 | N20: =A20-$A$5 -> 15 | O20: =IF(J20>0,LN(J20),"") -> 0.76214005 | P20: =COUNTIF(Data!$A$2:$A$2797,A20) -> 1
A21: =A20+1 -> 43903 | B21: =CHOOSE(WEEKDAY(A21,2),"Mon","Tue","Wed","Thu","Fri","Sat","Sun") -> Fri | C21: =SUMIFS(Data!$B$2:$B$2797,Data!$A$2:$A$2797,A21) -> 9 | D21: =SUMIFS(Data!$C$2:$C$2797,Data!$A$2:$A$2797,A21) -> 0 | E21: =SUMIFS(Data!$D$2:$D$2797,Data!$A$2:$A$2797,A21) -> 1 | F21: =SUM($C$5:C21) -> 30 | G21: =SUM($D$5:D21) -> 0 | H21: =SUM($E$5:E21) -> 3 | I21: =F21-G21-H21 -> 27 | J21: =AVERAGE(C15:C21) -> 3.4285714 | K21: =AVERAGE(D15:D21) -> 0 | L21: =IF(F21>0,G21/F21,0) -> 0 | M21: =IF(J14>0,J21/J14-1,"") -> 7 | N21: =A21-$A$5 -> 16 | O21: =IF(J21>0,LN(J21),"") -> 1.2321437 | P21: =COUNTIF(Data!$A$2:$A$2797,A21) -> 3
A22: =A21+1 -> 43904 | B22: =CHOOSE(WEEKDAY(A22,2),"Mon","Tue","Wed","Thu","Fri","Sat","Sun") -> Sat | C22: =SUMIFS(Data!$B$2:$B$2797,Data!$A$2:$A$2797,A22) -> 0 | D22: =SUMIFS(Data!$C$2:$C$2797,Data!$A$2:$A$2797,A22) -> 0 | E22: =SUMIFS(Data!$D$2:$D$2797,Data!$A$2:$A$2797,A22) -> 0 | F22: =SUM($C$5:C22) -> 30 | G22: =SUM($D$5:D22) -> 0 | H22: =SUM($E$5:E22) -> 3 | I22: =F22-G22-H22 -> 27 | J22: =AVERAGE(C16:C22) -> 3.2857143 | K22: =AVERAGE(D16:D22) -> 0 | L22: =IF(F22>0,G22/F22,0) -> 0 | M22: =IF(J15>0,J22/J15-1,"") -> 10.5 | N22: =A22-$A$5 -> 17 | O22: =IF(J22>0,LN(J22),"") -> 1.1895841 | P22: =COUNTIF(Data!$A$2:$A$2797,A22) -> 0
A23: =A22+1 -> 43905 | B23: =CHOOSE(WEEKDAY(A23,2),"Mon","Tue","Wed","Thu","Fri","Sat","Sun") -> Sun | C23: =SUMIFS(Data!$B$2:$B$2797,Data!$A$2:$A$2797,A23) -> 34 | D23: =SUMIFS(Data!$C$2:$C$2797,Data!$A$2:$A$2797,A23) -> 1 | E23: =SUMIFS(Data!$D$2:$D$2797,Data!$A$2:$A$2797,A23) -> 0 | F23: =SUM($C$5:C23) -> 64 | G23: =SUM($D$5:D23) -> 1 | H23: =SUM($E$5:E23) -> 3 | I23: =F23-G23-H23 -> 60 | J23: =AVERAGE(C17:C23) -> 8.1428571 | K23: =AVERAGE(D17:D23) -> 0.14285714 | L23: =IF(F23>0,G23/F23,0) -> 0.015625 | M23: =IF(J16>0,J23/J16-1,"") -> 27.5 | N23: =A23-$A$5 -> 18 | O23: =IF(J23>0,LN(J23),"") -> 2.0971411 | P23: =COUNTIF(Data!$A$2:$A$2797,A23) -> 5
A24: =A23+1 -> 43906 | B24: =CHOOSE(WEEKDAY(A24,2),"Mon","Tue","Wed","Thu","Fri","Sat","Sun") -> Mon | C24: =SUMIFS(Data!$B$2:$B$2797,Data!$A$2:$A$2797,A24) -> 151 | D24: =SUMIFS(Data!$C$2:$C$2797,Data!$A$2:$A$2797,A24) -> 0 | E24: =SUMIFS(Data!$D$2:$D$2797,Data!$A$2:$A$2797,A24) -> 1 | F24: =SUM($C$5:C24) -> 215 | G24: =SUM($D$5:D24) -> 1 | H24: =SUM($E$5:E24) -> 4 | I24: =F24-G24-H24 -> 210 | J24: =AVERAGE(C18:C24) -> 28.428571 | K24: =AVERAGE(D18:D24) -> 0.14285714 | L24: =IF(F24>0,G24/F24,0) -> 0.0046511628 | M24: =IF(J17>0,J24/J17-1,"") -> 18.9 | N24: =A24-$A$5 -> 19 | O24: =IF(J24>0,LN(J24),"") -> 3.3473947 | P24: =COUNTIF(Data!$A$2:$A$2797,A24) -> 7
A25: =A24+1 -> 43907 | B25: =CHOOSE(WEEKDAY(A25,2),"Mon","Tue","Wed","Thu","Fri","Sat","Sun") -> Tue | C25: =SUMIFS(Data!$B$2:$B$2797,Data!$A$2:$A$2797,A25) -> 52 | D25: =SUMIFS(Data!$C$2:$C$2797,Data!$A$2:$A$2797,A25) -> 0 | E25: =SUMIFS(Data!$D$2:$D$2797,Data!$A$2:$A$2797,A25) -> 0 | F25: =SUM($C$5:C25) -> 267 | G25: =SUM($D$5:D25) -> 1 | H25: =SUM($E$5:E25) -> 4 | I25: =F25-G25-H25 -> 262 | J25: =AVERAGE(C19:C25) -> 35.428571 | K25: =AVERAGE(D19:D25) -> 0.14285714 | L25: =IF(F25>0,G25/F25,0) -> 0.0037453184 | M25: =IF(J18>0,J25/J18-1,"") -> 18.076923 | N25: =A25-$A$5 -> 20 | O25: =IF(J25>0,LN(J25),"") -> 3.5675186 | P25: =COUNTIF(Data!$A$2:$A$2797,A25) -> 8
A26: =A25+1 -> 43908 | B26: =CHOOSE(WEEKDAY(A26,2),"Mon","Tue","Wed","Thu","Fri","Sat","Sun") -> Wed | C26: =SUMIFS(Data!$B$2:$B$2797,Data!$A$2:$A$2797,A26) -> 57 | D26: =SUMIFS(Data!$C$2:$C$2797,Data!$A$2:$A$2797,A26) -> 2 | E26: =SUMIFS(Data!$D$2:$D$2797,Data!$A$2:$A$2797,A26) -> 0 | F26: =SUM($C$5:C26) -> 324 | G26: =SUM($D$5:D26) -> 3 | H26: =SUM($E$5:E26) -> 4 | I26: =F26-G26-H26 -> 317 | J26: =AVERAGE(C20:C26) -> 43.428571 | K26: =AVERAGE(D20:D26) -> 0.42857143 | L26: =IF(F26>0,G26/F26,0) -> 0.0092592593 | M26: =IF(J19>0,J26/J19-1,"") -> 20.714286 | N26: =A26-$A$5 -> 21 | O26: =IF(J26>0,LN(J26),"") -> 3.7711176 | P26: =COUNTIF(Data!$A$2:$A$2797,A26) -> 9
A27: =A26+1 -> 43909 | B27: =CHOOSE(WEEKDAY(A27,2),"Mon","Tue","Wed","Thu","Fri","Sat","Sun") -> Thu | C27: =SUMIFS(Data!$B$2:$B$2797,Data!$A$2:$A$2797,A27) -> 154 | D27: =SUMIFS(Data!$C$2:$C$2797,Data!$A$2:$A$2797,A27) -> 0 | E27: =SUMIFS(Data!$D$2:$D$2797,Data!$A$2:$A$2797,A27) -> 1 | F27: =SUM($C$5:C27) -> 478 | G27: =SUM($D$5:D27) -> 3 | H27: =SUM($E$5:E27) -> 5 | I27: =F27-G27-H27 -> 470 | J27: =AVERAGE(C21:C27) -> 65.285714 | K27: =AVERAGE(D21:D27) -> 0.42857143 | L27: =IF(F27>0,G27/F27,0) -> 0.0062761506 | M27: =IF(J20>0,J27/J20-1,"") -> 29.466667 | N27: =A27-$A$5 -> 22 | O27: =IF(J27>0,LN(J27),"") -> 4.1787732 | P27: =COUNTIF(Data!$A$2:$A$2797,A27) -> 9
A28: =A27+1 -> 43910 | B28: =CHOOSE(WEEKDAY(A28,2),"Mon","Tue","Wed","Thu","Fri","Sat","Sun") -> Fri | C28: =SUMIFS(Data!$B$2:$B$2797,Data!$A$2:$A$2797,A28) -> 50 | D28: =SUMIFS(Data!$C$2:$C$2797,Data!$A$2:$A$2797,A28) -> 1 | E28: =SUMIFS(Data!$D$2:$D$2797,Data!$A$2:$A$2797,A28) -> 0 | F28: =SUM($C$5:C28) -> 528 | G28: =SUM($D$5:D28) -> 4 | H28: =SUM($E$5:E28) -> 5 | I28: =F28-G28-H28 -> 519 | J28: =AVERAGE(C22:C28) -> 71.142857 | K28: =AVERAGE(D22:D28) -> 0.57142857 | L28: =IF(F28>0,G28/F28,0) -> 0.0075757576 | M28: =IF(J21>0,J28/J21-1,"") -> 19.75 | N28: =A28-$A$5 -> 23 | O28: =IF(J28>0,LN(J28),"") -> 4.2646899 | P28: =COUNTIF(Data!$A$2:$A$2797,A28) -> 12
A29: =A28+1 -> 43911 | B29: =CHOOSE(WEEKDAY(A29,2),"Mon","Tue","Wed","Thu","Fri","Sat","Sun") -> Sat | C29: =SUMIFS(Data!$B$2:$B$2797,Data!$A$2:$A$2797,A29) -> 134 | D29: =SUMIFS(Data!$C$2:$C$2797,Data!$A$2:$A$2797,A29) -> 0 | E29: =SUMIFS(Data!$D$2:$D$2797,Data!$A$2:$A$2797,A29) -> 3 | F29: =SUM($C$5:C29) -> 662 | G29: =SUM($D$5:D29) -> 4 | H29: =SUM($E$5:E29) -> 8 | I29: =F29-G29-H29 -> 650 | J29: =AVERAGE(C23:C29) -> 90.285714 | K29: =AVERAGE(D23:D29) -> 0.57142857 | L29: =IF(F29>0,G29/F29,0) -> 0.0060422961 | M29: =IF(J22>0,J29/J22-1,"") -> 26.478261 | N29: =A29-$A$5 -> 24 | O29: =IF(J29>0,LN(J29),"") -> 4.5029792 | P29: =COUNTIF(Data!$A$2:$A$2797,A29) -> 14
... A103: =A102+1 -> 43985 | B103: =CHOOSE(WEEKDAY(A103,2),"Mon","Tue","Wed","Thu","Fri","Sat","Sun") -> Wed | C103: =SUMIFS(Data!$B$2:$B$2797,Data!$A$2:$A$2797,A103) -> 4677 | D103: =SUMIFS(Data!$C$2:$C$2797,Data!$A$2:$A$2797,A103) -> 82 | E103: =SUMIFS(Data!$D$2:$D$2797,Data!$A$2:$A$2797,A103) -> 1205 | F103: =SUM($C$5:C103) -> 83985 | G103: =SUM($D$5:D103) -> 1728 | H103: =SUM($E$5:E103) -> 24753 | I103: =F103-G103-H103 -> 57504 | J103: =AVERAGE(C97:C103) -> 3374 | K103: =AVERAGE(D97:D103) -> 73.428571 | L103: =IF(F103>0,G103/F103,0) -> 0.020575103 | M103: =IF(J96>0,J103/J96-1,"") -> 0.81119632 | N103: =A103-$A$5 -> 98 | O103: =IF(J103>0,LN(J103),"") -> 8.1238543 | P103: =COUNTIF(Data!$A$2:$A$2797,A103) -> 70
A105: Notes: 7-day averages start on day 7. Active cases = cumulative cases − deaths − recovered (same definition as the source dashboard). Cumulative CFR = cumulative deaths ÷ cumulative cases (crude, not lag-adjusted).

Sheet Weekly
A1: Weekly trend
A2: Weeks run for 7 days from the first reported day; the last week is partial and excluded from week-on-week change.
A4: Week | B4: Week start | C4: Week end | D4: Days | E4: Cases | F4: Deaths | G4: Recovered | H4: Avg cases per day | I4: Week-on-week change | J4: Status
A5: 1 | B5: =Daily!$A$5+7*(A5-1) -> 43887 | C5: =MIN(B5+6,MAX(Daily!$A$5:$A$103)) -> 43893 | D5: =C5-B5+1 -> 7 | E5: =SUMIFS(Daily!$C$5:$C$103,Daily!$A$5:$A$103,">="&B5,Daily!$A$5:$A$103,"<="&C5) -> 6 | F5: =SUMIFS(Daily!$D$5:$D$103,Daily!$A$5:$A$103,">="&B5,Daily!$A$5:$A$103,"<="&C5) -> 0 | G5: =SUMIFS(Daily!$E$5:$E$103,Daily!$A$5:$A$103,">="&B5,Daily!$A$5:$A$103,"<="&C5) -> 0 | H5: =E5/D5 -> 0.85714286 | J5: =IF(D5=7,"Full week","Partial") -> Full week
A6: 2 | B6: =Daily!$A$5+7*(A6-1) -> 43894 | C6: =MIN(B6+6,MAX(Daily!$A$5:$A$103)) -> 43900 | D6: =C6-B6+1 -> 7 | E6: =SUMIFS(Daily!$C$5:$C$103,Daily!$A$5:$A$103,">="&B6,Daily!$A$5:$A$103,"<="&C6) -> 13 | F6: =SUMIFS(Daily!$D$5:$D$103,Daily!$A$5:$A$103,">="&B6,Daily!$A$5:$A$103,"<="&C6) -> 0 | G6: =SUMIFS(Daily!$E$5:$E$103,Daily!$A$5:$A$103,">="&B6,Daily!$A$5:$A$103,"<="&C6) -> 1 | H6: =E6/D6 -> 1.8571429 | I6: =IF(AND(D6=7,D5=7,E5>0),E6/E5-1,"") -> 1.1666667 | J6: =IF(D6=7,"Full week","Partial") -> Full week
A7: 3 | B7: =Daily!$A$5+7*(A7-1) -> 43901 | C7: =MIN(B7+6,MAX(Daily!$A$5:$A$103)) -> 43907 | D7: =C7-B7+1 -> 7 | E7: =SUMIFS(Daily!$C$5:$C$103,Daily!$A$5:$A$103,">="&B7,Daily!$A$5:$A$103,"<="&C7) -> 248 | F7: =SUMIFS(Daily!$D$5:$D$103,Daily!$A$5:$A$103,">="&B7,Daily!$A$5:$A$103,"<="&C7) -> 1 | G7: =SUMIFS(Daily!$E$5:$E$103,Daily!$A$5:$A$103,">="&B7,Daily!$A$5:$A$103,"<="&C7) -> 3 | H7: =E7/D7 -> 35.428571 | I7: =IF(AND(D7=7,D6=7,E6>0),E7/E6-1,"") -> 18.076923 | J7: =IF(D7=7,"Full week","Partial") -> Full week
A8: 4 | B8: =Daily!$A$5+7*(A8-1) -> 43908 | C8: =MIN(B8+6,MAX(Daily!$A$5:$A$103)) -> 43914 | D8: =C8-B8+1 -> 7 | E8: =SUMIFS(Daily!$C$5:$C$103,Daily!$A$5:$A$103,">="&B8,Daily!$A$5:$A$103,"<="&C8) -> 701 | F8: =SUMIFS(Daily!$D$5:$D$103,Daily!$A$5:$A$103,">="&B8,Daily!$A$5:$A$103,"<="&C8) -> 6 | G8: =SUMIFS(Daily!$E$5:$E$103,Daily!$A$5:$A$103,">="&B8,Daily!$A$5:$A$103,"<="&C8) -> 22 | H8: =E8/D8 -> 100.14286 | I8: =IF(AND(D8=7,D7=7,E7>0),E8/E7-1,"") -> 1.8266129 | J8: =IF(D8=7,"Full week","Partial") -> Full week
A9: 5 | B9: =Daily!$A$5+7*(A9-1) -> 43915 | C9: =MIN(B9+6,MAX(Daily!$A$5:$A$103)) -> 43921 | D9: =C9-B9+1 -> 7 | E9: =SUMIFS(Daily!$C$5:$C$103,Daily!$A$5:$A$103,">="&B9,Daily!$A$5:$A$103,"<="&C9) -> 1002 | F9: =SUMIFS(Daily!$D$5:$D$103,Daily!$A$5:$A$103,">="&B9,Daily!$A$5:$A$103,"<="&C9) -> 20 | G9: =SUMIFS(Daily!$E$5:$E$103,Daily!$A$5:$A$103,">="&B9,Daily!$A$5:$A$103,"<="&C9) -> 96 | H9: =E9/D9 -> 143.14286 | I9: =IF(AND(D9=7,D8=7,E8>0),E9/E8-1,"") -> 0.42938659 | J9: =IF(D9=7,"Full week","Partial") -> Full week
A10: 6 | B10: =Daily!$A$5+7*(A10-1) -> 43922 | C10: =MIN(B10+6,MAX(Daily!$A$5:$A$103)) -> 43928 | D10: =C10-B10+1 -> 7 | E10: =SUMIFS(Daily!$C$5:$C$103,Daily!$A$5:$A$103,">="&B10,Daily!$A$5:$A$103,"<="&C10) -> 1297 | F10: =SUMIFS(Daily!$D$5:$D$103,Daily!$A$5:$A$103,">="&B10,Daily!$A$5:$A$103,"<="&C10) -> 29 | G10: =SUMIFS(Daily!$E$5:$E$103,Daily!$A$5:$A$103,">="&B10,Daily!$A$5:$A$103,"<="&C10) -> 365 | H10: =E10/D10 -> 185.28571 | I10: =IF(AND(D10=7,D9=7,E9>0),E10/E9-1,"") -> 0.29441118 | J10: =IF(D10=7,"Full week","Partial") -> Full week
A11: 7 | B11: =Daily!$A$5+7*(A11-1) -> 43929 | C11: =MIN(B11+6,MAX(Daily!$A$5:$A$103)) -> 43935 | D11: =C11-B11+1 -> 7 | E11: =SUMIFS(Daily!$C$5:$C$103,Daily!$A$5:$A$103,">="&B11,Daily!$A$5:$A$103,"<="&C11) -> 2718 | F11: =SUMIFS(Daily!$D$5:$D$103,Daily!$A$5:$A$103,">="&B11,Daily!$A$5:$A$103,"<="&C11) -> 52 | G11: =SUMIFS(Daily!$E$5:$E$103,Daily!$A$5:$A$103,">="&B11,Daily!$A$5:$A$103,"<="&C11) -> 634 | H11: =E11/D11 -> 388.28571 | I11: =IF(AND(D11=7,D10=7,E10>0),E11/E10-1,"") -> 1.0956052 | J11: =IF(D11=7,"Full week","Partial") -> Full week
A12: 8 | B12: =Daily!$A$5+7*(A12-1) -> 43936 | C12: =MIN(B12+6,MAX(Daily!$A$5:$A$103)) -> 43942 | D12: =C12-B12+1 -> 7 | E12: =SUMIFS(Daily!$C$5:$C$103,Daily!$A$5:$A$103,">="&B12,Daily!$A$5:$A$103,"<="&C12) -> 3768 | F12: =SUMIFS(Daily!$D$5:$D$103,Daily!$A$5:$A$103,">="&B12,Daily!$A$5:$A$103,"<="&C12) -> 101 | G12: =SUMIFS(Daily!$E$5:$E$103,Daily!$A$5:$A$103,">="&B12,Daily!$A$5:$A$103,"<="&C12) -> 718 | H12: =E12/D12 -> 538.28571 | I12: =IF(AND(D12=7,D11=7,E11>0),E12/E11-1,"") -> 0.38631347 | J12: =IF(D12=7,"Full week","Partial") -> Full week
A13: 9 | B13: =Daily!$A$5+7*(A13-1) -> 43943 | C13: =MIN(B13+6,MAX(Daily!$A$5:$A$103)) -> 43949 | D13: =C13-B13+1 -> 7 | E13: =SUMIFS(Daily!$C$5:$C$103,Daily!$A$5:$A$103,">="&B13,Daily!$A$5:$A$103,"<="&C13) -> 4993 | F13: =SUMIFS(Daily!$D$5:$D$103,Daily!$A$5:$A$103,">="&B13,Daily!$A$5:$A$103,"<="&C13) -> 86 | G13: =SUMIFS(Daily!$E$5:$E$103,Daily!$A$5:$A$103,">="&B13,Daily!$A$5:$A$103,"<="&C13) -> 626 | H13: =E13/D13 -> 713.28571 | I13: =IF(AND(D13=7,D12=7,E12>0),E13/E12-1,"") -> 0.32510616 | J13: =IF(D13=7,"Full week","Partial") -> Full week
A14: 10 | B14: =Daily!$A$5+7*(A14-1) -> 43950 | C14: =MIN(B14+6,MAX(Daily!$A$5:$A$103)) -> 43956 | D14: =C14-B14+1 -> 7 | E14: =SUMIFS(Daily!$C$5:$C$103,Daily!$A$5:$A$103,">="&B14,Daily!$A$5:$A$103,"<="&C14) -> 7223 | F14: =SUMIFS(Daily!$D$5:$D$103,Daily!$A$5:$A$103,">="&B14,Daily!$A$5:$A$103,"<="&C14) -> 163 | G14: =SUMIFS(Daily!$E$5:$E$103,Daily!$A$5:$A$103,">="&B14,Daily!$A$5:$A$103,"<="&C14) -> 415 | H14: =E14/D14 -> 1031.8571 | I14: =IF(AND(D14=7,D13=7,E13>0),E14/E13-1,"") -> 0.44662528 | J14: =IF(D14=7,"Full week","Partial") -> Full week
A15: 11 | B15: =Daily!$A$5+7*(A15-1) -> 43957 | C15: =MIN(B15+6,MAX(Daily!$A$5:$A$103)) -> 43963 | D15: =C15-B15+1 -> 7 | E15: =SUMIFS(Daily!$C$5:$C$103,Daily!$A$5:$A$103,">="&B15,Daily!$A$5:$A$103,"<="&C15) -> 11846 | F15: =SUMIFS(Daily!$D$5:$D$103,Daily!$A$5:$A$103,">="&B15,Daily!$A$5:$A$103,"<="&C15) -> 227 | G15: =SUMIFS(Daily!$E$5:$E$103,Daily!$A$5:$A$103,">="&B15,Daily!$A$5:$A$103,"<="&C15) -> 721 | H15: =E15/D15 -> 1692.2857 | I15: =IF(AND(D15=7,D14=7,E14>0),E15/E14-1,"") -> 0.64003877 | J15: =IF(D15=7,"Full week","Partial") -> Full week
A16: 12 | B16: =Daily!$A$5+7*(A16-1) -> 43964 | C16: =MIN(B16+6,MAX(Daily!$A$5:$A$103)) -> 43970 | D16: =C16-B16+1 -> 7 | E16: =SUMIFS(Daily!$C$5:$C$103,Daily!$A$5:$A$103,">="&B16,Daily!$A$5:$A$103,"<="&C16) -> 11397 | F16: =SUMIFS(Daily!$D$5:$D$103,Daily!$A$5:$A$103,">="&B16,Daily!$A$5:$A$103,"<="&C16) -> 261 | G16: =SUMIFS(Daily!$E$5:$E$103,Daily!$A$5:$A$103,">="&B16,Daily!$A$5:$A$103,"<="&C16) -> 4116 | H16: =E16/D16 -> 1628.1429 | I16: =IF(AND(D16=7,D15=7,E15>0),E16/E15-1,"") -> -0.03790309 | J16: =IF(D16=7,"Full week","Partial") -> Full week
A17: 13 | B17: =Daily!$A$5+7*(A17-1) -> 43971 | C17: =MIN(B17+6,MAX(Daily!$A$5:$A$103)) -> 43977 | D17: =C17-B17+1 -> 7 | E17: =SUMIFS(Daily!$C$5:$C$103,Daily!$A$5:$A$103,">="&B17,Daily!$A$5:$A$103,"<="&C17) -> 12982 | F17: =SUMIFS(Daily!$D$5:$D$103,Daily!$A$5:$A$103,">="&B17,Daily!$A$5:$A$103,"<="&C17) -> 232 | G17: =SUMIFS(Daily!$E$5:$E$103,Daily!$A$5:$A$103,">="&B17,Daily!$A$5:$A$103,"<="&C17) -> 5965 | H17: =E17/D17 -> 1854.5714 | I17: =IF(AND(D17=7,D16=7,E16>0),E17/E16-1,"") -> 0.13907169 | J17: =IF(D17=7,"Full week","Partial") -> Full week
... A19: 15 | B19: =Daily!$A$5+7*(A19-1) -> 43985 | C19: =MIN(B19+6,MAX(Daily!$A$5:$A$103)) -> 43985 | D19: =C19-B19+1 -> 1 | E19: =SUMIFS(Daily!$C$5:$C$103,Daily!$A$5:$A$103,">="&B19,Daily!$A$5:$A$103,"<="&C19) -> 4677 | F19: =SUMIFS(Daily!$D$5:$D$103,Daily!$A$5:$A$103,">="&B19,Daily!$A$5:$A$103,"<="&C19) -> 82 | G19: =SUMIFS(Daily!$E$5:$E$103,Daily!$A$5:$A$103,">="&B19,Daily!$A$5:$A$103,"<="&C19) -> 1205 | H19: =E19/D19 -> 4677 | I19: =IF(AND(D19=7,D18=7,E18>0),E19/E18-1,"") | J19: =IF(D19=7,"Full week","Partial") -> Partial
A20: Total | D20: =SUM(D5:D19) -> 99 | E20: =SUM(E5:E19) -> 83985 | F20: =SUM(F5:F19) -> 1728 | G20: =SUM(G5:G19) -> 24753 | H20: =E20/D20 -> 848.33333

Sheet Monthly
A1: Monthly summary
A2: February covers 26–29 Feb only and June covers 1–3 Jun only — compare months using the average-per-day column.
A4: Month | B4: Days covered | C4: Cases | D4: Deaths | E4: Recovered | F4: Avg cases per day | G4: CFR | H4: Change in avg/day vs prior month | I4: Share of all cases
A5: =DATE(YEAR(Daily!A5),MONTH(Daily!A5),1) -> 43862 | B5: =COUNTIFS(Daily!$A$5:$A$103,">="&A5,Daily!$A$5:$A$103,"<"&EDATE(A5,1)) -> 4 | C5: =SUMIFS(Daily!$C$5:$C$103,Daily!$A$5:$A$103,">="&A5,Daily!$A$5:$A$103,"<"&EDATE(A5,1)) -> 5 | D5: =SUMIFS(Daily!$D$5:$D$103,Daily!$A$5:$A$103,">="&A5,Daily!$A$5:$A$103,"<"&EDATE(A5,1)) -> 0 | E5: =SUMIFS(Daily!$E$5:$E$103,Daily!$A$5:$A$103,">="&A5,Daily!$A$5:$A$103,"<"&EDATE(A5,1)) -> 0 | F5: =IF(B5>0,C5/B5,0) -> 1.25 | G5: =IF(C5>0,D5/C5,0) -> 0 | I5: =C5/C$10 -> 5.9534441e-05
A6: =EDATE(A5,1) -> 43891 | B6: =COUNTIFS(Daily!$A$5:$A$103,">="&A6,Daily!$A$5:$A$103,"<"&EDATE(A6,1)) -> 31 | C6: =SUMIFS(Daily!$C$5:$C$103,Daily!$A$5:$A$103,">="&A6,Daily!$A$5:$A$103,"<"&EDATE(A6,1)) -> 1965 | D6: =SUMIFS(Daily!$D$5:$D$103,Daily!$A$5:$A$103,">="&A6,Daily!$A$5:$A$103,"<"&EDATE(A6,1)) -> 27 | E6: =SUMIFS(Daily!$E$5:$E$103,Daily!$A$5:$A$103,">="&A6,Daily!$A$5:$A$103,"<"&EDATE(A6,1)) -> 122 | F6: =IF(B6>0,C6/B6,0) -> 63.387097 | G6: =IF(C6>0,D6/C6,0) -> 0.013740458 | H6: =IF(F5>0,F6/F5-1,"") -> 49.709677 | I6: =C6/C$10 -> 0.023397035
A7: =EDATE(A6,1) -> 43922 | B7: =COUNTIFS(Daily!$A$5:$A$103,">="&A7,Daily!$A$5:$A$103,"<"&EDATE(A7,1)) -> 30 | C7: =SUMIFS(Daily!$C$5:$C$103,Daily!$A$5:$A$103,">="&A7,Daily!$A$5:$A$103,"<"&EDATE(A7,1)) -> 14389 | D7: =SUMIFS(Daily!$D$5:$D$103,Daily!$A$5:$A$103,">="&A7,Daily!$A$5:$A$103,"<"&EDATE(A7,1)) -> 302 | E7: =SUMIFS(Daily!$E$5:$E$103,Daily!$A$5:$A$103,">="&A7,Daily!$A$5:$A$103,"<"&EDATE(A7,1)) -> 2551 | F7: =IF(B7>0,C7/B7,0) -> 479.63333 | G7: =IF(C7>0,D7/C7,0) -> 0.020988255 | H7: =IF(F6>0,F7/F6-1,"") -> 6.5667345 | I7: =C7/C$10 -> 0.17132821
A8: =EDATE(A7,1) -> 43952 | B8: =COUNTIFS(Daily!$A$5:$A$103,">="&A8,Daily!$A$5:$A$103,"<"&EDATE(A8,1)) -> 31 | C8: =SUMIFS(Daily!$C$5:$C$103,Daily!$A$5:$A$103,">="&A8,Daily!$A$5:$A$103,"<"&EDATE(A8,1)) -> 54835 | D8: =SUMIFS(Daily!$D$5:$D$103,Daily!$A$5:$A$103,">="&A8,Daily!$A$5:$A$103,"<"&EDATE(A8,1)) -> 1170 | E8: =SUMIFS(Daily!$E$5:$E$103,Daily!$A$5:$A$103,">="&A8,Daily!$A$5:$A$103,"<"&EDATE(A8,1)) -> 17917 | F8: =IF(B8>0,C8/B8,0) -> 1768.871 | G8: =IF(C8>0,D8/C8,0) -> 0.021336737 | H8: =IF(F7>0,F8/F7-1,"") -> 2.687965 | I8: =C8/C$10 -> 0.65291421
A9: =EDATE(A8,1) -> 43983 | B9: =COUNTIFS(Daily!$A$5:$A$103,">="&A9,Daily!$A$5:$A$103,"<"&EDATE(A9,1)) -> 3 | C9: =SUMIFS(Daily!$C$5:$C$103,Daily!$A$5:$A$103,">="&A9,Daily!$A$5:$A$103,"<"&EDATE(A9,1)) -> 12791 | D9: =SUMIFS(Daily!$D$5:$D$103,Daily!$A$5:$A$103,">="&A9,Daily!$A$5:$A$103,"<"&EDATE(A9,1)) -> 229 | E9: =SUMIFS(Daily!$E$5:$E$103,Daily!$A$5:$A$103,">="&A9,Daily!$A$5:$A$103,"<"&EDATE(A9,1)) -> 4163 | F9: =IF(B9>0,C9/B9,0) -> 4263.6667 | G9: =IF(C9>0,D9/C9,0) -> 0.017903213 | H9: =IF(F8>0,F9/F8-1,"") -> 1.4103887 | I9: =C9/C$10 -> 0.15230101
A10: Total | B10: =SUM(B5:B9) -> 99 | C10: =SUM(C5:C9) -> 83985 | D10: =SUM(D5:D9) -> 1728 | E10: =SUM(E5:E9) -> 24753 | F10: =C10/B10 -> 848.33333 | G10: =D10/C10 -> 0.020575103 | I10: =SUM(I5:I9) -> 1

Sheet Province
A1: Province analysis
A2: Sorted by total cases. Shares and CFR are formulas on the Data sheet. Province names are as spelled in the source file.
A4: Province | B4: Cases | C4: Deaths | D4: Recovered (reported) | E4: Active (derived) | F4: Share of cases | G4: Share of deaths | H4: CFR | I4: Reported recovery rate | J4: Records | K4: CFR vs national (×)
A5: Sindh | B5: =SUMIF(Data!$F$2:$F$2797,$A5,Data!$B$2:$B$2797) -> 32858 | C5: =SUMIF(Data!$F$2:$F$2797,$A5,Data!$C$2:$C$2797) -> 546 | D5: =SUMIF(Data!$F$2:$F$2797,$A5,Data!$D$2:$D$2797) -> 15805 | E5: =B5-C5-D5 -> 16507 | F5: =B5/B$13 -> 0.39123653 | G5: =C5/C$13 -> 0.31597222 | H5: =IF(B5>0,C5/B5,0) -> 0.016616958 | I5: =IF(B5>0,D5/B5,0) -> 0.48100919 | J5: =COUNTIF(Data!$F$2:$F$2797,$A5) -> 529 | K5: =H5/$H$13 -> 0.80762454
A6: Punjab | B6: =SUMIF(Data!$F$2:$F$2797,$A6,Data!$B$2:$B$2797) -> 31096 | C6: =SUMIF(Data!$F$2:$F$2797,$A6,Data!$C$2:$C$2797) -> 593 | D6: =SUMIF(Data!$F$2:$F$2797,$A6,Data!$D$2:$D$2797) -> 4081 | E6: =B6-C6-D6 -> 26422 | F6: =B6/B$13 -> 0.37025659 | G6: =C6/C$13 -> 0.3431713 | H6: =IF(B6>0,C6/B6,0) -> 0.019069977 | I6: =IF(B6>0,D6/B6,0) -> 0.13123874 | J6: =COUNTIF(Data!$F$2:$F$2797,$A6) -> 341 | K6: =H6/$H$13 -> 0.92684723
A7: Khyber Pakhtunkhwa | B7: =SUMIF(Data!$F$2:$F$2797,$A7,Data!$B$2:$B$2797) -> 10259 | C7: =SUMIF(Data!$F$2:$F$2797,$A7,Data!$C$2:$C$2797) -> 473 | D7: =SUMIF(Data!$F$2:$F$2797,$A7,Data!$D$2:$D$2797) -> 1939 | E7: =B7-C7-D7 -> 7847 | F7: =B7/B$13 -> 0.12215277 | G7: =C7/C$13 -> 0.27372685 | H7: =IF(B7>0,C7/B7,0) -> 0.046105858 | I7: =IF(B7>0,D7/B7,0) -> 0.18900478 | J7: =COUNTIF(Data!$F$2:$F$2797,$A7) -> 1491 | K7: =H7/$H$13 -> 2.2408568
A8: Baluchistan | B8: =SUMIF(Data!$F$2:$F$2797,$A8,Data!$B$2:$B$2797) -> 5125 | C8: =SUMIF(Data!$F$2:$F$2797,$A8,Data!$C$2:$C$2797) -> 49 | D8: =SUMIF(Data!$F$2:$F$2797,$A8,Data!$D$2:$D$2797) -> 1981 | E8: =B8-C8-D8 -> 3095 | F8: =B8/B$13 -> 0.061022802 | G8: =C8/C$13 -> 0.028356481 | H8: =IF(B8>0,C8/B8,0) -> 0.0095609756 | I8: =IF(B8>0,D8/B8,0) -> 0.38653659 | J8: =COUNTIF(Data!$F$2:$F$2797,$A8) -> 83 | K8: =H8/$H$13 -> 0.46468665
A9: Islamabad Capital Territory | B9: =SUMIF(Data!$F$2:$F$2797,$A9,Data!$B$2:$B$2797) -> 3523 | C9: =SUMIF(Data!$F$2:$F$2797,$A9,Data!$C$2:$C$2797) -> 36 | D9: =SUMIF(Data!$F$2:$F$2797,$A9,Data!$D$2:$D$2797) -> 460 | E9: =B9-C9-D9 -> 3027 | F9: =B9/B$13 -> 0.041947967 | G9: =C9/C$13 -> 0.020833333 | H9: =IF(B9>0,C9/B9,0) -> 0.010218564 | I9: =IF(B9>0,D9/B9,0) -> 0.13057054 | J9: =COUNTIF(Data!$F$2:$F$2797,$A9) -> 74 | K9: =H9/$H$13 -> 0.49664703
A10: Gilgit-Baltistan | B10: =SUMIF(Data!$F$2:$F$2797,$A10,Data!$B$2:$B$2797) -> 786 | C10: =SUMIF(Data!$F$2:$F$2797,$A10,Data!$C$2:$C$2797) -> 24 | D10: =SUMIF(Data!$F$2:$F$2797,$A10,Data!$D$2:$D$2797) -> 362 | E10: =B10-C10-D10 -> 400 | F10: =B10/B$13 -> 0.0093588141 | G10: =C10/C$13 -> 0.013888889 | H10: =IF(B10>0,C10/B10,0) -> 0.030534351 | I10: =IF(B10>0,D10/B10,0) -> 0.4605598 | J10: =COUNTIF(Data!$F$2:$F$2797,$A10) -> 188 | K10: =H10/$H$13 -> 1.4840437
A11: Azad Jummu Kashmir | B11: =SUMIF(Data!$F$2:$F$2797,$A11,Data!$B$2:$B$2797) -> 285 | C11: =SUMIF(Data!$F$2:$F$2797,$A11,Data!$C$2:$C$2797) -> 6 | D11: =SUMIF(Data!$F$2:$F$2797,$A11,Data!$D$2:$D$2797) -> 110 | E11: =B11-C11-D11 -> 169 | F11: =B11/B$13 -> 0.0033934631 | G11: =C11/C$13 -> 0.0034722222 | H11: =IF(B11>0,C11/B11,0) -> 0.021052632 | I11: =IF(B11>0,D11/B11,0) -> 0.38596491 | J11: =COUNTIF(Data!$F$2:$F$2797,$A11) -> 54 | K11: =H11/$H$13 -> 1.0232091
A12: Federal Administration Tribal Area | B12: =SUMIF(Data!$F$2:$F$2797,$A12,Data!$B$2:$B$2797) -> 53 | C12: =SUMIF(Data!$F$2:$F$2797,$A12,Data!$C$2:$C$2797) -> 1 | D12: =SUMIF(Data!$F$2:$F$2797,$A12,Data!$D$2:$D$2797) -> 15 | E12: =B12-C12-D12 -> 37 | F12: =B12/B$13 -> 0.00063106507 | G12: =C12/C$13 -> 0.0005787037 | H12: =IF(B12>0,C12/B12,0) -> 0.018867925 | I12: =IF(B12>0,D12/B12,0) -> 0.28301887 | J12: =COUNTIF(Data!$F$2:$F$2797,$A12) -> 36 | K12: =H12/$H$13 -> 0.91702699
A13: Pakistan (total) | B13: =SUM(B5:B12) -> 83985 | C13: =SUM(C5:C12) -> 1728 | D13: =SUM(D5:D12) -> 24753 | E13: =SUM(E5:E12) -> 57504 | F13: =SUM(F5:F12) -> 1 | G13: =SUM(G5:G12) -> 1 | H13: =C13/B13 -> 0.020575103 | I13: =D13/B13 -> 0.2947312 | J13: =SUM(J5:J12) -> 2796 | K13: =H13/$H$13 -> 1
A14: Min. cases for comparisons (input) | B14: 1000
A15: Highest CFR (province, rate) | B15: =INDEX(A5:A12,MATCH(C15,H5:H12,0)) -> Khyber Pakhtunkhwa | C15: =_xlfn.MAXIFS(H5:H12,B5:B12,">="&$B$14) -> 0.046105858
A16: Recovery-rate range (min, max) | B16: =_xlfn.MINIFS(I5:I12,B5:B12,">="&$B$14) -> 0.13057054 | C16: =_xlfn.MAXIFS(I5:I12,B5:B12,">="&$B$14) -> 0.48100919
A17: Small provinces (GB, AJK, FATA) have few cases, so their CFR is volatile; the threshold above avoids ranking them. No population data is in the file, so per-capita rates are not calculated.
A19: Cases by province and month
A20: Province | B20: =Monthly!A5 -> 43862 | C20: =Monthly!A6 -> 43891 | D20: =Monthly!A7 -> 43922 | E20: =Monthly!A8 -> 43952 | F20: =Monthly!A9 -> 43983 | G20: Total | H20: Check vs table
A21: =A5 -> Sindh | B21: =SUMIFS(Data!$B$2:$B$2797,Data!$F$2:$F$2797,$A21,Data!$H$2:$H$2797,B$20) -> 3 | C21: =SUMIFS(Data!$B$2:$B$2797,Data!$F$2:$F$2797,$A21,Data!$H$2:$H$2797,C$20) -> 643 | D21: =SUMIFS(Data!$B$2:$B$2797,Data!$F$2:$F$2797,$A21,Data!$H$2:$H$2797,D$20) -> 5355 | E21: =SUMIFS(Data!$B$2:$B$2797,Data!$F$2:$F$2797,$A21,Data!$H$2:$H$2797,E$20) -> 22192 | F21: =SUMIFS(Data!$B$2:$B$2797,Data!$F$2:$F$2797,$A21,Data!$H$2:$H$2797,F$20) -> 4665 | G21: =SUM(B21:F21) -> 32858 | H21: =G21-B5 -> 0
A22: =A6 -> Punjab | B22: =SUMIFS(Data!$B$2:$B$2797,Data!$F$2:$F$2797,$A22,Data!$H$2:$H$2797,B$20) -> 0 | C22: =SUMIFS(Data!$B$2:$B$2797,Data!$F$2:$F$2797,$A22,Data!$H$2:$H$2797,C$20) -> 674 | D22: =SUMIFS(Data!$B$2:$B$2797,Data!$F$2:$F$2797,$A22,Data!$H$2:$H$2797,D$20) -> 5658 | E22: =SUMIFS(Data!$B$2:$B$2797,Data!$F$2:$F$2797,$A22,Data!$H$2:$H$2797,E$20) -> 19900 | F22: =SUMIFS(Data!$B$2:$B$2797,Data!$F$2:$F$2797,$A22,Data!$H$2:$H$2797,F$20) -> 4864 | G22: =SUM(B22:F22) -> 31096 | H22: =G22-B6 -> 0
A23: =A7 -> Khyber Pakhtunkhwa | B23: =SUMIFS(Data!$B$2:$B$2797,Data!$F$2:$F$2797,$A23,Data!$H$2:$H$2797,B$20) -> 0 | C23: =SUMIFS(Data!$B$2:$B$2797,Data!$F$2:$F$2797,$A23,Data!$H$2:$H$2797,C$20) -> 249 | D23: =SUMIFS(Data!$B$2:$B$2797,Data!$F$2:$F$2797,$A23,Data!$H$2:$H$2797,D$20) -> 1969 | E23: =SUMIFS(Data!$B$2:$B$2797,Data!$F$2:$F$2797,$A23,Data!$H$2:$H$2797,E$20) -> 6711 | F23: =SUMIFS(Data!$B$2:$B$2797,Data!$F$2:$F$2797,$A23,Data!$H$2:$H$2797,F$20) -> 1330 | G23: =SUM(B23:F23) -> 10259 | H23: =G23-B7 -> 0
A24: =A8 -> Baluchistan | B24: =SUMIFS(Data!$B$2:$B$2797,Data!$F$2:$F$2797,$A24,Data!$H$2:$H$2797,B$20) -> 0 | C24: =SUMIFS(Data!$B$2:$B$2797,Data!$F$2:$F$2797,$A24,Data!$H$2:$H$2797,C$20) -> 149 | D24: =SUMIFS(Data!$B$2:$B$2797,Data!$F$2:$F$2797,$A24,Data!$H$2:$H$2797,D$20) -> 883 | E24: =SUMIFS(Data!$B$2:$B$2797,Data!$F$2:$F$2797,$A24,Data!$H$2:$H$2797,E$20) -> 3262 | F24: =SUMIFS(Data!$B$2:$B$2797,Data!$F$2:$F$2797,$A24,Data!$H$2:$H$2797,F$20) -> 831 | G24: =SUM(B24:F24) -> 5125 | H24: =G24-B8 -> 0
A25: =A9 -> Islamabad Capital Territory | B25: =SUMIFS(Data!$B$2:$B$2797,Data!$F$2:$F$2797,$A25,Data!$H$2:$H$2797,B$20) -> 2 | C25: =SUMIFS(Data!$B$2:$B$2797,Data!$F$2:$F$2797,$A25,Data!$H$2:$H$2797,C$20) -> 52 | D25: =SUMIFS(Data!$B$2:$B$2797,Data!$F$2:$F$2797,$A25,Data!$H$2:$H$2797,D$20) -> 264 | E25: =SUMIFS(Data!$B$2:$B$2797,Data!$F$2:$F$2797,$A25,Data!$H$2:$H$2797,E$20) -> 2250 | F25: =SUMIFS(Data!$B$2:$B$2797,Data!$F$2:$F$2797,$A25,Data!$H$2:$H$2797,F$20) -> 955 | G25: =SUM(B25:F25) -> 3523 | H25: =G25-B9 -> 0
A26: =A10 -> Gilgit-Baltistan | B26: =SUMIFS(Data!$B$2:$B$2797,Data!$F$2:$F$2797,$A26,Data!$H$2:$H$2797,B$20) -> 0 | C26: =SUMIFS(Data!$B$2:$B$2797,Data!$F$2:$F$2797,$A26,Data!$H$2:$H$2797,C$20) -> 187 | D26: =SUMIFS(Data!$B$2:$B$2797,Data!$F$2:$F$2797,$A26,Data!$H$2:$H$2797,D$20) -> 152 | E26: =SUMIFS(Data!$B$2:$B$2797,Data!$F$2:$F$2797,$A26,Data!$H$2:$H$2797,E$20) -> 331 | F26: =SUMIFS(Data!$B$2:$B$2797,Data!$F$2:$F$2797,$A26,Data!$H$2:$H$2797,F$20) -> 116 | G26: =SUM(B26:F26) -> 786 | H26: =G26-B10 -> 0
A27: =A11 -> Azad Jummu Kashmir | B27: =SUMIFS(Data!$B$2:$B$2797,Data!$F$2:$F$2797,$A27,Data!$H$2:$H$2797,B$20) -> 0 | C27: =SUMIFS(Data!$B$2:$B$2797,Data!$F$2:$F$2797,$A27,Data!$H$2:$H$2797,C$20) -> 6 | D27: =SUMIFS(Data!$B$2:$B$2797,Data!$F$2:$F$2797,$A27,Data!$H$2:$H$2797,D$20) -> 60 | E27: =SUMIFS(Data!$B$2:$B$2797,Data!$F$2:$F$2797,$A27,Data!$H$2:$H$2797,E$20) -> 189 | F27: =SUMIFS(Data!$B$2:$B$2797,Data!$F$2:$F$2797,$A27,Data!$H$2:$H$2797,F$20) -> 30 | G27: =SUM(B27:F27) -> 285 | H27: =G27-B11 -> 0
A28: =A12 -> Federal Administration Tribal Area | B28: =SUMIFS(Data!$B$2:$B$2797,Data!$F$2:$F$2797,$A28,Data!$H$2:$H$2797,B$20) -> 0 | C28: =SUMIFS(Data!$B$2:$B$2797,Data!$F$2:$F$2797,$A28,Data!$H$2:$H$2797,C$20) -> 5 | D28: =SUMIFS(Data!$B$2:$B$2797,Data!$F$2:$F$2797,$A28,Data!$H$2:$H$2797,D$20) -> 48 | E28: =SUMIFS(Data!$B$2:$B$2797,Data!$F$2:$F$2797,$A28,Data!$H$2:$H$2797,E$20) -> 0 | F28: =SUMIFS(Data!$B$2:$B$2797,Data!$F$2:$F$2797,$A28,Data!$H$2:$H$2797,F$20) -> 0 | G28: =SUM(B28:F28) -> 53 | H28: =G28-B12 -> 0
A29: Pakistan (total) | B29: =SUM(B21:B28) -> 5 | C29: =SUM(C21:C28) -> 1965 | D29: =SUM(D21:D28) -> 14389 | E29: =SUM(E21:E28) -> 54835 | F29: =SUM(F21:F28) -> 12791 | G29: =SUM(G21:G28) -> 83985 | H29: =G29-B13 -> 0
A32: Share of each month's cases, by province
A33: Province | B33: =Monthly!A5 -> 43862 | C33: =Monthly!A6 -> 43891 | D33: =Monthly!A7 -> 43922 | E33: =Monthly!A8 -> 43952 | F33: =Monthly!A9 -> 43983
A34: =A5 -> Sindh | B34: =IF(B$29>0,B21/B$29,0) -> 0.6 | C34: =IF(C$29>0,C21/C$29,0) -> 0.32722646 | D34: =IF(D$29>0,D21/D$29,0) -> 0.37215929 | E34: =IF(E$29>0,E21/E$29,0) -> 0.40470502 | F34: =IF(F$29>0,F21/F$29,0) -> 0.36470956
A35: =A6 -> Punjab | B35: =IF(B$29>0,B22/B$29,0) -> 0 | C35: =IF(C$29>0,C22/C$29,0) -> 0.34300254 | D35: =IF(D$29>0,D22/D$29,0) -> 0.39321704 | E35: =IF(E$29>0,E22/E$29,0) -> 0.3629069 | F35: =IF(F$29>0,F22/F$29,0) -> 0.38026738
A36: =A7 -> Khyber Pakhtunkhwa | B36: =IF(B$29>0,B23/B$29,0) -> 0 | C36: =IF(C$29>0,C23/C$29,0) -> 0.12671756 | D36: =IF(D$29>0,D23/D$29,0) -> 0.13684064 | E36: =IF(E$29>0,E23/E$29,0) -> 0.12238534 | F36: =IF(F$29>0,F23/F$29,0) -> 0.10397936
A37: =A8 -> Baluchistan | B37: =IF(B$29>0,B24/B$29,0) -> 0 | C37: =IF(C$29>0,C24/C$29,0) -> 0.075826972 | D37: =IF(D$29>0,D24/D$29,0) -> 0.061366321 | E37: =IF(E$29>0,E24/E$29,0) -> 0.059487554 | F37: =IF(F$29>0,F24/F$29,0) -> 0.064967555
A38: =A9 -> Islamabad Capital Territory | B38: =IF(B$29>0,B25/B$29,0) -> 0.4 | C38: =IF(C$29>0,C25/C$29,0) -> 0.026463104 | D38: =IF(D$29>0,D25/D$29,0) -> 0.018347349 | E38: =IF(E$29>0,E25/E$29,0) -> 0.041032187 | F38: =IF(F$29>0,F25/F$29,0) -> 0.074661872
A39: =A10 -> Gilgit-Baltistan | B39: =IF(B$29>0,B26/B$29,0) -> 0 | C39: =IF(C$29>0,C26/C$29,0) -> 0.095165394 | D39: =IF(D$29>0,D26/D$29,0) -> 0.010563625 | E39: =IF(E$29>0,E26/E$29,0) -> 0.0060362907 | F39: =IF(F$29>0,F26/F$29,0) -> 0.0090688766
A40: =A11 -> Azad Jummu Kashmir | B40: =IF(B$29>0,B27/B$29,0) -> 0 | C40: =IF(C$29>0,C27/C$29,0) -> 0.0030534351 | D40: =IF(D$29>0,D27/D$29,0) -> 0.004169852 | E40: =IF(E$29>0,E27/E$29,0) -> 0.0034467037 | F40: =IF(F$29>0,F27/F$29,0) -> 0.0023453991
A41: =A12 -> Federal Administration Tribal Area | B41: =IF(B$29>0,B28/B$29,0) -> 0 | C41: =IF(C$29>0,C28/C$29,0) -> 0.0025445293 | D41: =IF(D$29>0,D28/D$29,0) -> 0.0033358816 | E41: =IF(E$29>0,E28/E$29,0) -> 0 | F41: =IF(F$29>0,F28/F$29,0) -> 0

Sheet City
A1: City analysis — top 15 cities by cases
A2: City province = province of the first record for that city (six tribal-district names appear under more than one province).
A4: Rank | B4: City | C4: Province | D4: Cases | E4: Deaths | F4: Recovered (reported) | G4: Share of cases | H4: Cumulative share | I4: CFR | J4: Reported recovery rate
A5: 1 | B5: Karachi | C5: =INDEX(Data!$F$2:$F$2797,MATCH(B5,Data!$G$2:$G$2797,0)) -> Sindh | D5: =SUMIF(Data!$G$2:$G$2797,$B5,Data!$B$2:$B$2797) -> 29346 | E5: =SUMIF(Data!$G$2:$G$2797,$B5,Data!$C$2:$C$2797) -> 498 | F5: =SUMIF(Data!$G$2:$G$2797,$B5,Data!$D$2:$D$2797) -> 13248 | G5: =D5/D$21 -> 0.34941954 | H5: =SUM(G$5:G5) -> 0.34941954 | I5: =IF(D5>0,E5/D5,0) -> 0.016969945 | J5: =IF(D5>0,F5/D5,0) -> 0.45144142
A6: 2 | B6: Lahore | C6: =INDEX(Data!$F$2:$F$2797,MATCH(B6,Data!$G$2:$G$2797,0)) -> Punjab | D6: =SUMIF(Data!$G$2:$G$2797,$B6,Data!$B$2:$B$2797) -> 28015 | E6: =SUMIF(Data!$G$2:$G$2797,$B6,Data!$C$2:$C$2797) -> 582 | F6: =SUMIF(Data!$G$2:$G$2797,$B6,Data!$D$2:$D$2797) -> 3853 | G6: =D6/D$21 -> 0.33357147 | H6: =SUM(G$5:G6) -> 0.68299101 | I6: =IF(D6>0,E6/D6,0) -> 0.020774585 | J6: =IF(D6>0,F6/D6,0) -> 0.13753346
A7: 3 | B7: Quetta | C7: =INDEX(Data!$F$2:$F$2797,MATCH(B7,Data!$G$2:$G$2797,0)) -> Baluchistan | D7: =SUMIF(Data!$G$2:$G$2797,$B7,Data!$B$2:$B$2797) -> 5109 | E7: =SUMIF(Data!$G$2:$G$2797,$B7,Data!$C$2:$C$2797) -> 49 | F7: =SUMIF(Data!$G$2:$G$2797,$B7,Data!$D$2:$D$2797) -> 1981 | G7: =D7/D$21 -> 0.060832291 | H7: =SUM(G$5:G7) -> 0.7438233 | I7: =IF(D7>0,E7/D7,0) -> 0.009590918 | J7: =IF(D7>0,F7/D7,0) -> 0.38774711
A8: 4 | B8: Peshawar | C8: =INDEX(Data!$F$2:$F$2797,MATCH(B8,Data!$G$2:$G$2797,0)) -> Khyber Pakhtunkhwa | D8: =SUMIF(Data!$G$2:$G$2797,$B8,Data!$B$2:$B$2797) -> 4923 | E8: =SUMIF(Data!$G$2:$G$2797,$B8,Data!$C$2:$C$2797) -> 265 | F8: =SUMIF(Data!$G$2:$G$2797,$B8,Data!$D$2:$D$2797) -> 407 | G8: =D8/D$21 -> 0.05861761 | H8: =SUM(G$5:G8) -> 0.80244091 | I8: =IF(D8>0,E8/D8,0) -> 0.053828966 | J8: =IF(D8>0,F8/D8,0) -> 0.082673167
A9: 5 | B9: Islamabad | C9: =INDEX(Data!$F$2:$F$2797,MATCH(B9,Data!$G$2:$G$2797,0)) -> Islamabad Capital Territory | D9: =SUMIF(Data!$G$2:$G$2797,$B9,Data!$B$2:$B$2797) -> 3523 | E9: =SUMIF(Data!$G$2:$G$2797,$B9,Data!$C$2:$C$2797) -> 36 | F9: =SUMIF(Data!$G$2:$G$2797,$B9,Data!$D$2:$D$2797) -> 460 | G9: =D9/D$21 -> 0.041947967 | H9: =SUM(G$5:G9) -> 0.84438888 | I9: =IF(D9>0,E9/D9,0) -> 0.010218564 | J9: =IF(D9>0,F9/D9,0) -> 0.13057054
A10: 6 | B10: Swat | C10: =INDEX(Data!$F$2:$F$2797,MATCH(B10,Data!$G$2:$G$2797,0)) -> Khyber Pakhtunkhwa | D10: =SUMIF(Data!$G$2:$G$2797,$B10,Data!$B$2:$B$2797) -> 958 | E10: =SUMIF(Data!$G$2:$G$2797,$B10,Data!$C$2:$C$2797) -> 45 | F10: =SUMIF(Data!$G$2:$G$2797,$B10,Data!$D$2:$D$2797) -> 266 | G10: =D10/D$21 -> 0.011406799 | H10: =SUM(G$5:G10) -> 0.85579568 | I10: =IF(D10>0,E10/D10,0) -> 0.04697286 | J10: =IF(D10>0,F10/D10,0) -> 0.2776618
A11: 7 | B11: Multan | C11: =INDEX(Data!$F$2:$F$2797,MATCH(B11,Data!$G$2:$G$2797,0)) -> Punjab | D11: =SUMIF(Data!$G$2:$G$2797,$B11,Data!$B$2:$B$2797) -> 712 | E11: =SUMIF(Data!$G$2:$G$2797,$B11,Data!$C$2:$C$2797) -> 2 | F11: =SUMIF(Data!$G$2:$G$2797,$B11,Data!$D$2:$D$2797) -> 1 | G11: =D11/D$21 -> 0.0084777044 | H11: =SUM(G$5:G11) -> 0.86427338 | I11: =IF(D11>0,E11/D11,0) -> 0.0028089888 | J11: =IF(D11>0,F11/D11,0) -> 0.0014044944
A12: 8 | B12: Sukkur | C12: =INDEX(Data!$F$2:$F$2797,MATCH(B12,Data!$G$2:$G$2797,0)) -> Sindh | D12: =SUMIF(Data!$G$2:$G$2797,$B12,Data!$B$2:$B$2797) -> 681 | E12: =SUMIF(Data!$G$2:$G$2797,$B12,Data!$C$2:$C$2797) -> 5 | F12: =SUMIF(Data!$G$2:$G$2797,$B12,Data!$D$2:$D$2797) -> 488 | G12: =D12/D$21 -> 0.0081085908 | H12: =SUM(G$5:G12) -> 0.87238197 | I12: =IF(D12>0,E12/D12,0) -> 0.0073421439 | J12: =IF(D12>0,F12/D12,0) -> 0.71659325
A13: 9 | B13: Hyderabad | C13: =INDEX(Data!$F$2:$F$2797,MATCH(B13,Data!$G$2:$G$2797,0)) -> Sindh | D13: =SUMIF(Data!$G$2:$G$2797,$B13,Data!$B$2:$B$2797) -> 610 | E13: =SUMIF(Data!$G$2:$G$2797,$B13,Data!$C$2:$C$2797) -> 11 | F13: =SUMIF(Data!$G$2:$G$2797,$B13,Data!$D$2:$D$2797) -> 459 | G13: =D13/D$21 -> 0.0072632018 | H13: =SUM(G$5:G13) -> 0.87964517 | I13: =IF(D13>0,E13/D13,0) -> 0.018032787 | J13: =IF(D13>0,F13/D13,0) -> 0.75245902
A14: 10 | B14: Raiwind | C14: =INDEX(Data!$F$2:$F$2797,MATCH(B14,Data!$G$2:$G$2797,0)) -> Punjab | D14: =SUMIF(Data!$G$2:$G$2797,$B14,Data!$B$2:$B$2797) -> 546 | E14: =SUMIF(Data!$G$2:$G$2797,$B14,Data!$C$2:$C$2797) -> 1 | F14: =SUMIF(Data!$G$2:$G$2797,$B14,Data!$D$2:$D$2797) -> 1 | G14: =D14/D$21 -> 0.0065011609 | H14: =SUM(G$5:G14) -> 0.88614634 | I14: =IF(D14>0,E14/D14,0) -> 0.0018315018 | J14: =IF(D14>0,F14/D14,0) -> 0.0018315018
A15: 11 | B15: Malakand | C15: =INDEX(Data!$F$2:$F$2797,MATCH(B15,Data!$G$2:$G$2797,0)) -> Khyber Pakhtunkhwa | D15: =SUMIF(Data!$G$2:$G$2797,$B15,Data!$B$2:$B$2797) -> 486 | E15: =SUMIF(Data!$G$2:$G$2797,$B15,Data!$C$2:$C$2797) -> 16 | F15: =SUMIF(Data!$G$2:$G$2797,$B15,Data!$D$2:$D$2797) -> 99 | G15: =D15/D$21 -> 0.0057867476 | H15: =SUM(G$5:G15) -> 0.89193308 | I15: =IF(D15>0,E15/D15,0) -> 0.032921811 | J15: =IF(D15>0,F15/D15,0) -> 0.2037037
A16: 12 | B16: Mardan | C16: =INDEX(Data!$F$2:$F$2797,MATCH(B16,Data!$G$2:$G$2797,0)) -> Khyber Pakhtunkhwa | D16: =SUMIF(Data!$G$2:$G$2797,$B16,Data!$B$2:$B$2797) -> 473 | E16: =SUMIF(Data!$G$2:$G$2797,$B16,Data!$C$2:$C$2797) -> 24 | F16: =SUMIF(Data!$G$2:$G$2797,$B16,Data!$D$2:$D$2797) -> 146 | G16: =D16/D$21 -> 0.0056319581 | H16: =SUM(G$5:G16) -> 0.89756504 | I16: =IF(D16>0,E16/D16,0) -> 0.050739958 | J16: =IF(D16>0,F16/D16,0) -> 0.30866808
... A19: 15 | B19: Ghotki | C19: =INDEX(Data!$F$2:$F$2797,MATCH(B19,Data!$G$2:$G$2797,0)) -> Sindh | D19: =SUMIF(Data!$G$2:$G$2797,$B19,Data!$B$2:$B$2797) -> 376 | E19: =SUMIF(Data!$G$2:$G$2797,$B19,Data!$C$2:$C$2797) -> 1 | F19: =SUMIF(Data!$G$2:$G$2797,$B19,Data!$D$2:$D$2797) -> 146 | G19: =D19/D$21 -> 0.0044769899 | H19: =SUM(G$5:G19) -> 0.91156754 | I19: =IF(D19>0,E19/D19,0) -> 0.0026595745 | J19: =IF(D19>0,F19/D19,0) -> 0.38829787
B20: All other cities | D20: =D21-SUM(D5:D19) -> 7427 | E20: =E21-SUM(E5:E19) -> 182 | F20: =F21-SUM(F5:F19) -> 2795 | G20: =D20/D$21 -> 0.088432458 | H20: =H19+G20 -> 1 | I20: =IF(D20>0,E20/D20,0) -> 0.024505184 | J20: =IF(D20>0,F20/D20,0) -> 0.37632961
B21: Pakistan (total) | D21: =SUM(Data!$B$2:$B$2797) -> 83985 | E21: =SUM(Data!$C$2:$C$2797) -> 1728 | F21: =SUM(Data!$D$2:$D$2797) -> 24753 | G21: =SUM(G5:G20) -> 1 | I21: =E21/D21 -> 0.020575103 | J21: =F21/D21 -> 0.2947312
A23: The file has 117 distinct city names (counted in Python from the Clean sheet). A city with a high case count but near-zero reported recoveries (e.g. Multan, Raiwind) signals under-reported recoveries rather than real outcomes.

Sheet Travel
A1: Source of infection (travel history)
A2: Group mapping in column B is an analyst assumption (blue = editable input); totals recalculate if you change it.
A4: Travel history | B4: Group (assumption) | C4: Cases | D4: Deaths | E4: Records | F4: Share of cases | G4: CFR
A5: Local - Social Contact | B5: Local transmission | C5: =SUMIF(Data!$E$2:$E$2797,$A5,Data!$B$2:$B$2797) -> 78118 | D5: =SUMIF(Data!$E$2:$E$2797,$A5,Data!$C$2:$C$2797) -> 1627 | E5: =COUNTIF(Data!$E$2:$E$2797,$A5) -> 2533 | F5: =C5/C$20 -> 0.93014229 | G5: =IF(C5>0,D5/C5,0) -> 0.020827466
A6: Unknown | B6: Unknown source | C6: =SUMIF(Data!$E$2:$E$2797,$A6,Data!$B$2:$B$2797) -> 3459 | D6: =SUMIF(Data!$E$2:$E$2797,$A6,Data!$C$2:$C$2797) -> 84 | E6: =COUNTIF(Data!$E$2:$E$2797,$A6) -> 123 | F6: =C6/C$20 -> 0.041185926 | G6: =IF(C6>0,D6/C6,0) -> 0.024284475
A7: Tableeghi Jamaat | B7: Cluster / institutional | C7: =SUMIF(Data!$E$2:$E$2797,$A7,Data!$B$2:$B$2797) -> 1115 | D7: =SUMIF(Data!$E$2:$E$2797,$A7,Data!$C$2:$C$2797) -> 5 | E7: =COUNTIF(Data!$E$2:$E$2797,$A7) -> 23 | F7: =C7/C$20 -> 0.01327618 | G7: =IF(C7>0,D7/C7,0) -> 0.0044843049
A8: Iran/Taftan | B8: Travel-linked (imported) | C8: =SUMIF(Data!$E$2:$E$2797,$A8,Data!$B$2:$B$2797) -> 1053 | D8: =SUMIF(Data!$E$2:$E$2797,$A8,Data!$C$2:$C$2797) -> 11 | E8: =COUNTIF(Data!$E$2:$E$2797,$A8) -> 88 | F8: =C8/C$20 -> 0.012537953 | G8: =IF(C8>0,D8/C8,0) -> 0.010446344
A9: Jail | B9: Cluster / institutional | C9: =SUMIF(Data!$E$2:$E$2797,$A9,Data!$B$2:$B$2797) -> 107 | D9: =SUMIF(Data!$E$2:$E$2797,$A9,Data!$C$2:$C$2797) -> 0 | E9: =COUNTIF(Data!$E$2:$E$2797,$A9) -> 5 | F9: =C9/C$20 -> 0.001274037 | G9: =IF(C9>0,D9/C9,0) -> 0
A10: Afghanistan | B10: Travel-linked (imported) | C10: =SUMIF(Data!$E$2:$E$2797,$A10,Data!$B$2:$B$2797) -> 70 | D10: =SUMIF(Data!$E$2:$E$2797,$A10,Data!$C$2:$C$2797) -> 0 | E10: =COUNTIF(Data!$E$2:$E$2797,$A10) -> 5 | F10: =C10/C$20 -> 0.00083348217 | G10: =IF(C10>0,D10/C10,0) -> 0
A11: International Passenger | B11: Travel-linked (imported) | C11: =SUMIF(Data!$E$2:$E$2797,$A11,Data!$B$2:$B$2797) -> 38 | D11: =SUMIF(Data!$E$2:$E$2797,$A11,Data!$C$2:$C$2797) -> 0 | E11: =COUNTIF(Data!$E$2:$E$2797,$A11) -> 5 | F11: =C11/C$20 -> 0.00045246175 | G11: =IF(C11>0,D11/C11,0) -> 0
A12: Syria | B12: Travel-linked (imported) | C12: =SUMIF(Data!$E$2:$E$2797,$A12,Data!$B$2:$B$2797) -> 7 | D12: =SUMIF(Data!$E$2:$E$2797,$A12,Data!$C$2:$C$2797) -> 0 | E12: =COUNTIF(Data!$E$2:$E$2797,$A12) -> 2 | F12: =C12/C$20 -> 8.3348217e-05 | G12: =IF(C12>0,D12/C12,0) -> 0
A13: KSA | B13: Travel-linked (imported) | C13: =SUMIF(Data!$E$2:$E$2797,$A13,Data!$B$2:$B$2797) -> 6 | D13: =SUMIF(Data!$E$2:$E$2797,$A13,Data!$C$2:$C$2797) -> 1 | E13: =COUNTIF(Data!$E$2:$E$2797,$A13) -> 2 | F13: =C13/C$20 -> 7.1441329e-05 | G13: =IF(C13>0,D13/C13,0) -> 0.16666667
A14: UK | B14: Travel-linked (imported) | C14: =SUMIF(Data!$E$2:$E$2797,$A14,Data!$B$2:$B$2797) -> 5 | D14: =SUMIF(Data!$E$2:$E$2797,$A14,Data!$C$2:$C$2797) -> 0 | E14: =COUNTIF(Data!$E$2:$E$2797,$A14) -> 3 | F14: =C14/C$20 -> 5.9534441e-05 | G14: =IF(C14>0,D14/C14,0) -> 0
A15: China | B15: Travel-linked (imported) | C15: =SUMIF(Data!$E$2:$E$2797,$A15,Data!$B$2:$B$2797) -> 2 | D15: =SUMIF(Data!$E$2:$E$2797,$A15,Data!$C$2:$C$2797) -> 0 | E15: =COUNTIF(Data!$E$2:$E$2797,$A15) -> 2 | F15: =C15/C$20 -> 2.3813776e-05 | G15: =IF(C15>0,D15/C15,0) -> 0
A16: India | B16: Travel-linked (imported) | C16: =SUMIF(Data!$E$2:$E$2797,$A16,Data!$B$2:$B$2797) -> 2 | D16: =SUMIF(Data!$E$2:$E$2797,$A16,Data!$C$2:$C$2797) -> 0 | E16: =COUNTIF(Data!$E$2:$E$2797,$A16) -> 1 | F16: =C16/C$20 -> 2.3813776e-05 | G16: =IF(C16>0,D16/C16,0) -> 0
... A19: USA | B19: Travel-linked (imported) | C19: =SUMIF(Data!$E$2:$E$2797,$A19,Data!$B$2:$B$2797) -> 1 | D19: =SUMIF(Data!$E$2:$E$2797,$A19,Data!$C$2:$C$2797) -> 0 | E19: =COUNTIF(Data!$E$2:$E$2797,$A19) -> 1 | F19: =C19/C$20 -> 1.1906888e-05 | G19: =IF(C19>0,D19/C19,0) -> 0
A20: Total | C20: =SUM(C5:C19) -> 83985 | D20: =SUM(D5:D19) -> 1728 | E20: =SUM(E5:E19) -> 2796 | F20: =SUM(F5:F19) -> 1 | G20: =D20/C20 -> 0.020575103
A22: By group
A23: Group | B23: Cases | C23: Deaths | D23: Share of cases | E23: CFR
A24: Local transmission | B24: =SUMIF($B$5:$B$19,$A24,$C$5:$C$19) -> 78119 | C24: =SUMIF($B$5:$B$19,$A24,$D$5:$D$19) -> 1627 | D24: =B24/B$28 -> 0.93015419 | E24: =IF(B24>0,C24/B24,0) -> 0.0208272
A25: Cluster / institutional | B25: =SUMIF($B$5:$B$19,$A25,$C$5:$C$19) -> 1222 | C25: =SUMIF($B$5:$B$19,$A25,$D$5:$D$19) -> 5 | D25: =B25/B$28 -> 0.014550217 | E25: =IF(B25>0,C25/B25,0) -> 0.004091653
A26: Travel-linked (imported) | B26: =SUMIF($B$5:$B$19,$A26,$C$5:$C$19) -> 1185 | C26: =SUMIF($B$5:$B$19,$A26,$D$5:$D$19) -> 12 | D26: =B26/B$28 -> 0.014109662 | E26: =IF(B26>0,C26/B26,0) -> 0.010126582
A27: Unknown source | B27: =SUMIF($B$5:$B$19,$A27,$C$5:$C$19) -> 3459 | C27: =SUMIF($B$5:$B$19,$A27,$D$5:$D$19) -> 84 | D27: =B27/B$28 -> 0.041185926 | E27: =IF(B27>0,C27/B27,0) -> 0.024284475
A28: Total | B28: =SUM(B24:B27) -> 83985 | C28: =SUM(C24:C27) -> 1728 | D28: =SUM(D24:D27) -> 1 | E28: =C28/B28 -> 0.020575103
A30: Travel history is a recorded field, not a contact-tracing result: "Local - Social Contact" is the default for most records, and 4% of cases have no known source.

Sheet Statistics
A1: Statistical analysis
A2: Descriptive statistics, outliers, weekday pattern, case-to-death lag and growth-rate fit — all computed from the Daily sheet.
A3: 1. Descriptive statistics (per calendar day)
A4: Metric | B4: Daily cases | C4: Daily deaths | D4: Daily recovered
A5: Days | B5: =COUNT(Daily!$C$5:$C$103) -> 99 | C5: =COUNT(Daily!$D$5:$D$103) -> 99 | D5: =COUNT(Daily!$E$5:$E$103) -> 99
A6: Total | B6: =SUM(Daily!$C$5:$C$103) -> 83985 | C6: =SUM(Daily!$D$5:$D$103) -> 1728 | D6: =SUM(Daily!$E$5:$E$103) -> 24753
A7: Mean | B7: =AVERAGE(Daily!$C$5:$C$103) -> 848.33333 | C7: =AVERAGE(Daily!$D$5:$D$103) -> 17.454545 | D7: =AVERAGE(Daily!$E$5:$E$103) -> 250.0303
A8: Median | B8: =MEDIAN(Daily!$C$5:$C$103) -> 512 | C8: =MEDIAN(Daily!$D$5:$D$103) -> 8 | D8: =MEDIAN(Daily!$E$5:$E$103) -> 39
A9: Standard deviation | B9: =STDEV(Daily!$C$5:$C$103) -> 1008.4617 | C9: =STDEV(Daily!$D$5:$D$103) -> 20.957816 | D9: =STDEV(Daily!$E$5:$E$103) -> 450.90574
A10: Coefficient of variation | B10: =STDEV(Daily!$C$5:$C$103)/AVERAGE(Daily!$C$5:$C$103) -> 1.1887564 | C10: =STDEV(Daily!$D$5:$D$103)/AVERAGE(Daily!$D$5:$D$103) -> 1.2007082 | D10: =STDEV(Daily!$E$5:$E$103)/AVERAGE(Daily!$E$5:$E$103) -> 1.8034044
A11: Minimum | B11: =MIN(Daily!$C$5:$C$103) -> 0 | C11: =MIN(Daily!$D$5:$D$103) -> 0 | D11: =MIN(Daily!$E$5:$E$103) -> 0
A12: Quartile 1 | B12: =QUARTILE(Daily!$C$5:$C$103,1) -> 97 | C12: =QUARTILE(Daily!$D$5:$D$103,1) -> 1 | D12: =QUARTILE(Daily!$E$5:$E$103,1) -> 0.5
A13: Quartile 3 | B13: =QUARTILE(Daily!$C$5:$C$103,3) -> 1401.5 | C13: =QUARTILE(Daily!$D$5:$D$103,3) -> 30 | D13: =QUARTILE(Daily!$E$5:$E$103,3) -> 217
A14: Interquartile range | B14: =QUARTILE(Daily!$C$5:$C$103,3)-QUARTILE(Daily!$C$5:$C$103,1) -> 1304.5 | C14: =QUARTILE(Daily!$D$5:$D$103,3)-QUARTILE(Daily!$D$5:$D$103,1) -> 29 | D14: =QUARTILE(Daily!$E$5:$E$103,3)-QUARTILE(Daily!$E$5:$E$103,1) -> 216.5
A15: Maximum | B15: =MAX(Daily!$C$5:$C$103) -> 4677 | C15: =MAX(Daily!$D$5:$D$103) -> 88 | D15: =MAX(Daily!$E$5:$E$103) -> 2072
A16: Skewness | B16: =SKEW(Daily!$C$5:$C$103) -> 1.5736122 | C16: =SKEW(Daily!$D$5:$D$103) -> 1.4949248 | D16: =SKEW(Daily!$E$5:$E$103) -> 2.3010052
A17: Mean far above median and high skewness mean a few very large late-period days dominate the average: use the median and the 7-day average when describing a "typical" day.
A19: 2. Outlier screen — daily cases (Tukey fence)
A20: Upper fence (Q3 + 1.5 × IQR) | B20: =B13+1.5*B14 -> 3358.25
A21: Days above the fence | B21: =COUNTIF(Daily!$C$5:$C$103,">"&B20) -> 3
A22: First day above the fence | B22: =_xlfn.MINIFS(Daily!$A$5:$A$103,Daily!$C$5:$C$103,">"&B20) -> 43983
A23: Share of all cases on those days | B23: =SUMIF(Daily!$C$5:$C$103,">"&B20)/B6 -> 0.15230101
A24: Flagged days are bunched at the end of the period (see first-day date), consistent with accelerating spread rather than isolated data errors. No days were removed.
A26: 3. Day-of-week pattern
A27: Day | B27: Avg cases | C27: Index (all-day mean = 100) | D27: Avg deaths | E27: Days in sample
